<robot
  name="edo_sim">
  <link
    name="base_link">
    <inertial>
      <origin
        xyz="0.0617583602130883 0.437262464550775 -0.00395442197852672"
        rpy="0 0 0" />
      <mass
        value="7.49" />
      <inertia
        ixx="0.460329866170721"
        ixy="0.454307543819724"
        ixz="0.101042057002983"
        iyy="0.0114904737104093"
        iyz="0.0104051602860671"
        izz="0.00004800141659469" />
    </inertial>
    <visual>
      <origin
        xyz="0 0 0"
        rpy="0 0 0" />
      <geometry>
        <mesh
          filename="package://edo_sim/meshes/base_link.STL" />
      </geometry>
      <material
        name="">
        <color
          rgba="0.792156862745098 0.819607843137255 0.933333333333333 1" />
      </material>
    </visual>
    <collision>
      <origin
        xyz="0 0 0"
        rpy="0 0 0" />
      <geometry>
        <mesh
          filename="package://edo_sim/meshes/base_link.STL" />
      </geometry>
    </collision>
  </link>
  <link
    name="link_1">
    <inertial>
      <origin
        xyz="-0.00457048841401064 0.303831811417004 -0.00202866410579916"
        rpy="0 0 0" />
      <mass
        value="2.071768" />
      <inertia
        ixx="0.460329866170721"
        ixy="0.454307543819724"
        ixz="0.101042057002983"
        iyy="0.0114904737104093"
        iyz="0.0104051602860671"
        izz="0.00004800141659469" />
    </inertial>
    <visual>
      <origin
        xyz="0 0 0"
        rpy="0 0 0" />
      <geometry>
        <mesh
          filename="package://edo_sim/meshes/link_1.STL" />
      </geometry>
      <material
        name="">
        <color
          rgba="0.792156862745098 0.819607843137255 0.933333333333333 1" />
      </material>
    </visual>
    <collision>
      <origin
        xyz="0 0 0"
        rpy="0 0 0" />
      <geometry>
        <mesh
          filename="package://edo_sim/meshes/link_1.STL" />
      </geometry>
    </collision>
  </link>
  <joint
    name="joint_1"
    type="continuous">
    <origin
      xyz="0.057188 0.0059831 0.13343"
      rpy="1.5708 6.9389E-16 -3.1416" />
    <parent
      link="base_link" />
    <child
      link="link_1" />
    <axis
      xyz="0 1 0" />
  </joint>
  <link
    name="link_2">
    <inertial>
      <origin
        xyz="-0.0168406485709407 0.071318237296396 -0.0876822373080704"
        rpy="0 0 0" />
      <mass
        value="1.333978" />
      <inertia
        ixx="0.460329866170721"
        ixy="0.454307543819724"
        ixz="0.101042057002983"
        iyy="0.0114904737104093"
        iyz="0.0104051602860671"
        izz="0.00004800141659469" />
    </inertial>
    <visual>
      <origin
        xyz="0 0 0"
        rpy="0 0 0" />
      <geometry>
        <mesh
          filename="package://edo_sim/meshes/link_2.STL" />
      </geometry>
      <material
        name="">
        <color
          rgba="0.792156862745098 0.819607843137255 0.933333333333333 1" />
      </material>
    </visual>
    <collision>
      <origin
        xyz="0 0 0"
        rpy="0 0 0" />
      <geometry>
        <mesh
          filename="package://edo_sim/meshes/link_2.STL" />
      </geometry>
    </collision>
  </link>
  <joint
    name="joint_2"
    type="continuous">
    <origin
      xyz="0 0.18967 0"
      rpy="0.94237 -0.4634 -0.11653" />
    <parent
      link="link_1" />
    <child
      link="link_2" />
    <axis
      xyz="-0.88847 0.2908 0.35504" />
  </joint>
  <link
    name="link_3">
    <inertial>
      <origin
        xyz="0.00457048841401063 0.0962524890074447 0.00395442197852662"
        rpy="0 0 0" />
      <mass
        value="6.22909E-01" />
      <inertia
        ixx="0.460329866170721"
        ixy="0.454307543819724"
        ixz="0.101042057002983"
        iyy="0.0114904737104093"
        iyz="0.0104051602860671"
        izz="0.00004800141659469" />
    </inertial>
    <visual>
      <origin
        xyz="0 0 0"
        rpy="0 0 0" />
      <geometry>
        <mesh
          filename="package://edo_sim/meshes/link_3.STL" />
      </geometry>
      <material
        name="">
        <color
          rgba="0.792156862745098 0.819607843137255 0.933333333333333 1" />
      </material>
    </visual>
    <collision>
      <origin
        xyz="0 0 0"
        rpy="0 0 0" />
      <geometry>
        <mesh
          filename="package://edo_sim/meshes/link_3.STL" />
      </geometry>
    </collision>
  </link>
  <joint
    name="joint_3"
    type="continuous">
    <origin
      xyz="-0.024558 0.12737 -0.16578"
      rpy="0.97336 -0.36296 2.8253" />
    <parent
      link="link_2" />
    <child
      link="link_3" />
    <axis
      xyz="1 0 0" />
  </joint>
  <link
    name="link_4">
    <inertial>
      <origin
        xyz="-0.00422951158597114 -0.00395442197852627 0.255057059248813"
        rpy="0 0 0" />
      <mass
        value="5.2005E-01" />
      <inertia
        ixx="0.460329866170721"
        ixy="0.454307543819724"
        ixz="0.101042057002983"
        iyy="0.0114904737104093"
        iyz="0.0104051602860671"
        izz="0.00004800141659469" />
    </inertial>
    <visual>
      <origin
        xyz="0 0 0"
        rpy="0 0 0" />
      <geometry>
        <mesh
          filename="package://edo_sim/meshes/link_4.STL" />
      </geometry>
      <material
        name="">
        <color
          rgba="0.792156862745098 0.819607843137255 0.933333333333333 1" />
      </material>
    </visual>
    <collision>
      <origin
        xyz="0 0 0"
        rpy="0 0 0" />
      <geometry>
        <mesh
          filename="package://edo_sim/meshes/link_4.STL" />
      </geometry>
    </collision>
  </link>
  <joint
    name="joint_4"
    type="continuous">
    <origin
      xyz="0.0088 -0.1588 0"
      rpy="-1.5708 0 0" />
    <parent
      link="link_3" />
    <child
      link="link_4" />
    <axis
      xyz="0 0 -1" />
  </joint>
  <link
    name="link_5">
    <inertial>
      <origin
        xyz="0.00422951158596777 -0.00395442197852616 -0.360352489007445"
        rpy="0 0 0" />
      <mass
        value="5.41662E-01" />
      <inertia
        ixx="0.460329866170721"
        ixy="0.454307543819724"
        ixz="0.101042057002983"
        iyy="0.0114904737104093"
        iyz="0.0104051602860671"
        izz="0.00004800141659469" />
    </inertial>
    <visual>
      <origin
        xyz="0 0 0"
        rpy="0 0 0" />
      <geometry>
        <mesh
          filename="package://edo_sim/meshes/link_5.STL" />
      </geometry>
      <material
        name="">
        <color
          rgba="0.792156862745098 0.819607843137255 0.933333333333333 1" />
      </material>
    </visual>
    <collision>
      <origin
        xyz="0 0 0"
        rpy="0 0 0" />
      <geometry>
        <mesh
          filename="package://edo_sim/meshes/link_5.STL" />
      </geometry>
    </collision>
  </link>
  <joint
    name="joint_5"
    type="continuous">
    <origin
      xyz="0 0 -0.1053"
      rpy="3.1416 1.1102E-14 3.1416" />
    <parent
      link="link_4" />
    <child
      link="link_5" />
    <axis
      xyz="-1 0 0" />
  </joint>
  <link
    name="link_6">
    <inertial>
      <origin
        xyz="1.10581233290358E-05 -0.00932339385603209 6.35624315718574E-06"
        rpy="0 0 0" />
      <mass
        value="9.5445E-02" />
      <inertia
        ixx="0.460329866170721"
        ixy="0.454307543819724"
        ixz="0.101042057002983"
        iyy="0.0114904737104093"
        iyz="0.0104051602860671"
        izz="0.00004800141659469" />
    </inertial>
    <visual>
      <origin
        xyz="0 0 0"
        rpy="0 0 0" />
      <geometry>
        <mesh
          filename="package://edo_sim/meshes/link_6.STL" />
      </geometry>
      <material
        name="">
        <color
          rgba="0.792156862745098 0.819607843137255 0.933333333333333 1" />
      </material>
    </visual>
    <collision>
      <origin
        xyz="0 0 0"
        rpy="0 0 0" />
      <geometry>
        <mesh
          filename="package://edo_sim/meshes/link_6.STL" />
      </geometry>
    </collision>
  </link>
  <joint
    name="joint_6"
    type="continuous">
    <origin
      xyz="-0.0039 0 0.1636"
      rpy="-1.5708 1.249E-14 0" />
    <parent
      link="link_5" />
    <child
      link="link_6" />
    <axis
      xyz="0 -1 0" />
  </joint>
</robot>